{
 "cells": [
  {
   "cell_type": "code",
   "execution_count": 38,
   "metadata": {},
   "outputs": [],
   "source": [
    "import sys\n",
    "import os\n",
    "\n",
    "# Chemin absolu du répertoire racine du projet\n",
    "project_root = '/home/conite/Documents/WORKSPACE/PROJECTS/BI-PROJECT/BANK-REVIEWS-INTELLIGENCE/'\n",
    "\n",
    "# Ajouter le répertoire src au chemin de recherche des modules\n",
    "src_dir = os.path.join(project_root, 'src')\n",
    "sys.path.append(src_dir)\n",
    "\n"
   ]
  },
  {
   "cell_type": "code",
   "execution_count": 39,
   "metadata": {},
   "outputs": [
    {
     "name": "stdout",
     "output_type": "stream",
     "text": [
      "/home/conite/Documents/WORKSPACE/PROJECTS/BI-PROJECT/BANK-REVIEWS-INTELLIGENCE/data/parquet/2024-07-30/Morocco/Nador.parquet: 90 rows\n",
      "Macro table saved at: /home/conite/Documents/WORKSPACE/PROJECTS/BI-PROJECT/BANK-REVIEWS-INTELLIGENCE/src/macro_table/macro_table.parquet\n",
      "Macro table saved as CSV at : /home/conite/Documents/WORKSPACE/PROJECTS/BI-PROJECT/BANK-REVIEWS-INTELLIGENCE/src/macro_table/macro_table.csv\n",
      "0    Pays Ahsan\n",
      "1        Berger\n",
      "2           NAN\n",
      "3           NAN\n",
      "4           NAN\n",
      "Name: Reviewer_Text, dtype: object\n",
      "    Country   Town  ... Reviewer_Owner_Reply Reviewer_Owner_Reply_Date\n",
      "0   Morocco  Nador  ...                  NAN                      None\n",
      "1   Morocco  Nador  ...                  NAN                      None\n",
      "2   Morocco  Nador  ...                  NAN                      None\n",
      "3   Morocco  Nador  ...                  NAN                      None\n",
      "4   Morocco  Nador  ...                  NAN                      None\n",
      "..      ...    ...  ...                  ...                       ...\n",
      "85  Morocco  Nador  ...                  NAN                      None\n",
      "86  Morocco  Nador  ...                  NAN                      None\n",
      "87  Morocco  Nador  ...                  NAN                      None\n",
      "88  Morocco  Nador  ...                  NAN                      None\n",
      "89  Morocco  Nador  ...                  NAN                      None\n",
      "\n",
      "[90 rows x 14 columns]\n",
      "     Country   Town  ... Sentiments        Sub_Topics\n",
      "0    Morocco  Nador  ...   Positive  Customer Service\n",
      "1    Morocco  Nador  ...   Positive           General\n",
      "2    Morocco  Nador  ...    Neutral           General\n",
      "3    Morocco  Nador  ...    Neutral           General\n",
      "4    Morocco  Nador  ...    Neutral           General\n",
      "..       ...    ...  ...        ...               ...\n",
      "453  Morocco  Nador  ...   Positive           General\n",
      "454  Morocco  Nador  ...   Positive           General\n",
      "455      NaN    NaN  ...   Negative      Incompetence\n",
      "456  Morocco  Nador  ...   Positive          Location\n",
      "457  Morocco  Nador  ...   Negative      Incompetence\n",
      "\n",
      "[458 rows x 17 columns]\n",
      "Error creating database and user: connection to server at \"localhost\" (127.0.0.1), port 5432 failed: FATAL:  password authentication failed for user \"postgres\"\n",
      "connection to server at \"localhost\" (127.0.0.1), port 5432 failed: FATAL:  password authentication failed for user \"postgres\"\n",
      "\n",
      "Traceback (most recent call last):\n",
      "  File \"/home/conite/.pyenv/versions/3.11.0/lib/python3.11/site-packages/sqlalchemy/engine/base.py\", line 2228, in _wrap_pool_connect\n",
      "    return fn()\n",
      "           ^^^^\n",
      "  File \"/home/conite/.pyenv/versions/3.11.0/lib/python3.11/site-packages/sqlalchemy/pool.py\", line 434, in connect\n",
      "    return _ConnectionFairy._checkout(self)\n",
      "           ^^^^^^^^^^^^^^^^^^^^^^^^^^^^^^^^\n",
      "  File \"/home/conite/.pyenv/versions/3.11.0/lib/python3.11/site-packages/sqlalchemy/pool.py\", line 831, in _checkout\n",
      "    fairy = _ConnectionRecord.checkout(pool)\n",
      "            ^^^^^^^^^^^^^^^^^^^^^^^^^^^^^^^^\n",
      "  File \"/home/conite/.pyenv/versions/3.11.0/lib/python3.11/site-packages/sqlalchemy/pool.py\", line 563, in checkout\n",
      "    rec = pool._do_get()\n",
      "          ^^^^^^^^^^^^^^\n",
      "  File \"/home/conite/.pyenv/versions/3.11.0/lib/python3.11/site-packages/sqlalchemy/pool.py\", line 1258, in _do_get\n",
      "    with util.safe_reraise():\n",
      "  File \"/home/conite/.pyenv/versions/3.11.0/lib/python3.11/site-packages/sqlalchemy/util/langhelpers.py\", line 67, in __exit__\n",
      "    compat.reraise(exc_type, exc_value, exc_tb)\n",
      "  File \"/home/conite/.pyenv/versions/3.11.0/lib/python3.11/site-packages/sqlalchemy/util/compat.py\", line 277, in reraise\n",
      "    raise value\n",
      "  File \"/home/conite/.pyenv/versions/3.11.0/lib/python3.11/site-packages/sqlalchemy/pool.py\", line 1256, in _do_get\n",
      "    return self._create_connection()\n",
      "           ^^^^^^^^^^^^^^^^^^^^^^^^^\n",
      "  File \"/home/conite/.pyenv/versions/3.11.0/lib/python3.11/site-packages/sqlalchemy/pool.py\", line 379, in _create_connection\n",
      "    return _ConnectionRecord(self)\n",
      "           ^^^^^^^^^^^^^^^^^^^^^^^\n",
      "  File \"/home/conite/.pyenv/versions/3.11.0/lib/python3.11/site-packages/sqlalchemy/pool.py\", line 508, in __init__\n",
      "    self.__connect(first_connect_check=True)\n",
      "  File \"/home/conite/.pyenv/versions/3.11.0/lib/python3.11/site-packages/sqlalchemy/pool.py\", line 710, in __connect\n",
      "    connection = pool._invoke_creator(self)\n",
      "                 ^^^^^^^^^^^^^^^^^^^^^^^^^^\n",
      "  File \"/home/conite/.pyenv/versions/3.11.0/lib/python3.11/site-packages/sqlalchemy/engine/strategies.py\", line 114, in connect\n",
      "    return dialect.connect(*cargs, **cparams)\n",
      "           ^^^^^^^^^^^^^^^^^^^^^^^^^^^^^^^^^^\n",
      "  File \"/home/conite/.pyenv/versions/3.11.0/lib/python3.11/site-packages/sqlalchemy/engine/default.py\", line 437, in connect\n",
      "    return self.dbapi.connect(*cargs, **cparams)\n",
      "           ^^^^^^^^^^^^^^^^^^^^^^^^^^^^^^^^^^^^^\n",
      "  File \"/home/conite/.pyenv/versions/3.11.0/lib/python3.11/site-packages/psycopg2/__init__.py\", line 122, in connect\n",
      "    conn = _connect(dsn, connection_factory=connection_factory, **kwasync)\n",
      "           ^^^^^^^^^^^^^^^^^^^^^^^^^^^^^^^^^^^^^^^^^^^^^^^^^^^^^^^^^^^^^^^\n",
      "psycopg2.OperationalError: connection to server at \"localhost\" (127.0.0.1), port 5432 failed: FATAL:  password authentication failed for user \"conite\"\n",
      "connection to server at \"localhost\" (127.0.0.1), port 5432 failed: FATAL:  password authentication failed for user \"conite\"\n",
      "\n",
      "\n",
      "The above exception was the direct cause of the following exception:\n",
      "\n",
      "Traceback (most recent call last):\n",
      "  File \"/home/conite/Documents/WORKSPACE/PROJECTS/BI-PROJECT/BANK-REVIEWS-INTELLIGENCE/src/main.py\", line 138, in <module>\n",
      "    main()\n",
      "  File \"/home/conite/Documents/WORKSPACE/PROJECTS/BI-PROJECT/BANK-REVIEWS-INTELLIGENCE/src/main.py\", line 134, in main\n",
      "    Base.metadata.create_all(engine)\n",
      "  File \"/home/conite/.pyenv/versions/3.11.0/lib/python3.11/site-packages/sqlalchemy/sql/schema.py\", line 4199, in create_all\n",
      "    bind._run_visitor(\n",
      "  File \"/home/conite/.pyenv/versions/3.11.0/lib/python3.11/site-packages/sqlalchemy/engine/base.py\", line 2010, in _run_visitor\n",
      "    with self._optional_conn_ctx_manager(connection) as conn:\n",
      "  File \"/home/conite/.pyenv/versions/3.11.0/lib/python3.11/contextlib.py\", line 137, in __enter__\n",
      "    return next(self.gen)\n",
      "           ^^^^^^^^^^^^^^\n",
      "  File \"/home/conite/.pyenv/versions/3.11.0/lib/python3.11/site-packages/sqlalchemy/engine/base.py\", line 2002, in _optional_conn_ctx_manager\n",
      "    with self.contextual_connect() as conn:\n",
      "         ^^^^^^^^^^^^^^^^^^^^^^^^^\n",
      "  File \"/home/conite/.pyenv/versions/3.11.0/lib/python3.11/site-packages/sqlalchemy/engine/base.py\", line 2192, in contextual_connect\n",
      "    self._wrap_pool_connect(self.pool.connect, None),\n",
      "    ^^^^^^^^^^^^^^^^^^^^^^^^^^^^^^^^^^^^^^^^^^^^^^^^\n",
      "  File \"/home/conite/.pyenv/versions/3.11.0/lib/python3.11/site-packages/sqlalchemy/engine/base.py\", line 2231, in _wrap_pool_connect\n",
      "    Connection._handle_dbapi_exception_noconnection(\n",
      "  File \"/home/conite/.pyenv/versions/3.11.0/lib/python3.11/site-packages/sqlalchemy/engine/base.py\", line 1528, in _handle_dbapi_exception_noconnection\n",
      "    util.raise_from_cause(sqlalchemy_exception, exc_info)\n",
      "  File \"/home/conite/.pyenv/versions/3.11.0/lib/python3.11/site-packages/sqlalchemy/util/compat.py\", line 296, in raise_from_cause\n",
      "    reraise(type(exception), exception, tb=exc_tb, cause=cause)\n",
      "  File \"/home/conite/.pyenv/versions/3.11.0/lib/python3.11/site-packages/sqlalchemy/util/compat.py\", line 276, in reraise\n",
      "    raise value.with_traceback(tb)\n",
      "  File \"/home/conite/.pyenv/versions/3.11.0/lib/python3.11/site-packages/sqlalchemy/engine/base.py\", line 2228, in _wrap_pool_connect\n",
      "    return fn()\n",
      "           ^^^^\n",
      "  File \"/home/conite/.pyenv/versions/3.11.0/lib/python3.11/site-packages/sqlalchemy/pool.py\", line 434, in connect\n",
      "    return _ConnectionFairy._checkout(self)\n",
      "           ^^^^^^^^^^^^^^^^^^^^^^^^^^^^^^^^\n",
      "  File \"/home/conite/.pyenv/versions/3.11.0/lib/python3.11/site-packages/sqlalchemy/pool.py\", line 831, in _checkout\n",
      "    fairy = _ConnectionRecord.checkout(pool)\n",
      "            ^^^^^^^^^^^^^^^^^^^^^^^^^^^^^^^^\n",
      "  File \"/home/conite/.pyenv/versions/3.11.0/lib/python3.11/site-packages/sqlalchemy/pool.py\", line 563, in checkout\n",
      "    rec = pool._do_get()\n",
      "          ^^^^^^^^^^^^^^\n",
      "  File \"/home/conite/.pyenv/versions/3.11.0/lib/python3.11/site-packages/sqlalchemy/pool.py\", line 1258, in _do_get\n",
      "    with util.safe_reraise():\n",
      "  File \"/home/conite/.pyenv/versions/3.11.0/lib/python3.11/site-packages/sqlalchemy/util/langhelpers.py\", line 67, in __exit__\n",
      "    compat.reraise(exc_type, exc_value, exc_tb)\n",
      "  File \"/home/conite/.pyenv/versions/3.11.0/lib/python3.11/site-packages/sqlalchemy/util/compat.py\", line 277, in reraise\n",
      "    raise value\n",
      "  File \"/home/conite/.pyenv/versions/3.11.0/lib/python3.11/site-packages/sqlalchemy/pool.py\", line 1256, in _do_get\n",
      "    return self._create_connection()\n",
      "           ^^^^^^^^^^^^^^^^^^^^^^^^^\n",
      "  File \"/home/conite/.pyenv/versions/3.11.0/lib/python3.11/site-packages/sqlalchemy/pool.py\", line 379, in _create_connection\n",
      "    return _ConnectionRecord(self)\n",
      "           ^^^^^^^^^^^^^^^^^^^^^^^\n",
      "  File \"/home/conite/.pyenv/versions/3.11.0/lib/python3.11/site-packages/sqlalchemy/pool.py\", line 508, in __init__\n",
      "    self.__connect(first_connect_check=True)\n",
      "  File \"/home/conite/.pyenv/versions/3.11.0/lib/python3.11/site-packages/sqlalchemy/pool.py\", line 710, in __connect\n",
      "    connection = pool._invoke_creator(self)\n",
      "                 ^^^^^^^^^^^^^^^^^^^^^^^^^^\n",
      "  File \"/home/conite/.pyenv/versions/3.11.0/lib/python3.11/site-packages/sqlalchemy/engine/strategies.py\", line 114, in connect\n",
      "    return dialect.connect(*cargs, **cparams)\n",
      "           ^^^^^^^^^^^^^^^^^^^^^^^^^^^^^^^^^^\n",
      "  File \"/home/conite/.pyenv/versions/3.11.0/lib/python3.11/site-packages/sqlalchemy/engine/default.py\", line 437, in connect\n",
      "    return self.dbapi.connect(*cargs, **cparams)\n",
      "           ^^^^^^^^^^^^^^^^^^^^^^^^^^^^^^^^^^^^^\n",
      "  File \"/home/conite/.pyenv/versions/3.11.0/lib/python3.11/site-packages/psycopg2/__init__.py\", line 122, in connect\n",
      "    conn = _connect(dsn, connection_factory=connection_factory, **kwasync)\n",
      "           ^^^^^^^^^^^^^^^^^^^^^^^^^^^^^^^^^^^^^^^^^^^^^^^^^^^^^^^^^^^^^^^\n",
      "sqlalchemy.exc.OperationalError: (psycopg2.OperationalError) connection to server at \"localhost\" (127.0.0.1), port 5432 failed: FATAL:  password authentication failed for user \"conite\"\n",
      "connection to server at \"localhost\" (127.0.0.1), port 5432 failed: FATAL:  password authentication failed for user \"conite\"\n",
      " (Background on this error at: http://sqlalche.me/e/e3q8)\n"
     ]
    }
   ],
   "source": [
    "!python main.py\n"
   ]
  },
  {
   "cell_type": "code",
   "execution_count": 1,
   "metadata": {},
   "outputs": [
    {
     "name": "stdout",
     "output_type": "stream",
     "text": [
      "Requirement already satisfied: termcolor in /home/conite/.pyenv/versions/3.11.0/lib/python3.11/site-packages (2.4.0)\n"
     ]
    }
   ],
   "source": [
    "!pip install termcolor"
   ]
  },
  {
   "cell_type": "code",
   "execution_count": null,
   "metadata": {},
   "outputs": [],
   "source": []
  }
 ],
 "metadata": {
  "kernelspec": {
   "display_name": "Python 3",
   "language": "python",
   "name": "python3"
  },
  "language_info": {
   "codemirror_mode": {
    "name": "ipython",
    "version": 3
   },
   "file_extension": ".py",
   "mimetype": "text/x-python",
   "name": "python",
   "nbconvert_exporter": "python",
   "pygments_lexer": "ipython3",
   "version": "3.11.0"
  }
 },
 "nbformat": 4,
 "nbformat_minor": 2
}
